<?xml version="1.0"?>
<robot xmlns:xacro="http://www.ros.org/wiki/xacro" name="arduinobot">

    <link name="world"/>
    <!-- Base Link -->
    <link name="base_link">
        <visual>
            <origin rpy="0 0 0" xyz="0 0 0"/>
            <geometry>
                <mesh filename="package://arduinobot_description/meshes/basement_1.dae" scale="5 5 5"/>
            </geometry>
            <material name="dark_grey">
                <color rgba="0.3 0.3 0.3 1.0"/>
            </material>
        </visual>
        <collision>
            <origin rpy="0 0 0" xyz="0 0 0"/>
            <geometry>
                <cylinder radius="0.06" length="0.04"/>
            </geometry>
        </collision>
        <inertial>
            <origin xyz="0 0 0.02" rpy="0 0 0"/>
            <mass value="0.5"/>
            <inertia ixx="0.00015" ixy="0.0" ixz="0.0" 
                    iyy="0.00015" iyz="0.0" 
                    izz="0.00025"/>
        </inertial>
    </link>
    
    <joint name="virtual_joint" type="fixed">
        <parent link="world"/>
        <child link="base_link"/>
        <origin rpy="0 0 0" xyz="0 0 0"/>
    </joint>

    <!-- Base Plate -->
    <link name="base_plate">
        <visual>
            <origin rpy="0 0 0" xyz="0 0 0"/>
            <geometry>
                <mesh filename="package://arduinobot_description/meshes/base_plate_2.dae" scale="5 5 5"/>
            </geometry>
            <material name="blue">
                <color rgba="0.2 0.2 0.8 1.0"/>
            </material>
        </visual>
        <collision>
            <origin rpy="0 0 0" xyz="0 0 0"/>
            <geometry>
                <cylinder radius="0.04" length="0.04"/>
            </geometry>
        </collision>
        <inertial>
            <origin xyz="0 0 0" rpy="0 0 0"/>
            <mass value="0.3"/>
            <inertia ixx="0.0001" ixy="0.0" ixz="0.0" 
                    iyy="0.0001" iyz="0.0" 
                    izz="0.00015"/>
        </inertial>
    </link>

    <joint name="base_to_base_plate" type="revolute">
        <parent link="base_link"/>
        <child link="base_plate"/>
        <origin rpy="0 0 0" xyz="0 0 0.009"/>
        <axis xyz="0 0 1"/>
        <limit lower="-${PI_2}" upper="${PI_2}" effort="${effort}" velocity="${velocity}"/>
        <dynamics damping="0.5" friction="0.1"/>
    </joint>
</robot>
