<?xml version="1.0"?>
<robot xmlns:xacro="http://www.ros.org/wiki/xacro">

    <!-- Gripper Links -->
    <link name="gripper_1">
        <visual>
            <origin rpy="0 0 0" xyz="0 0 0"/>
            <geometry>
                <mesh filename="package://arduinobot_description/meshes/gripper_1.dae" scale="5 5 5"/>
            </geometry>
            <material name="grey">
                <color rgba="0.7 0.7 0.7 1.0"/>
            </material>
        </visual>
        <collision>
            <origin rpy="0 0 0" xyz="0 0 0"/>
            <geometry>
                <box size="0.02 0.04 0.02"/>
            </geometry>
        </collision>
        <inertial>
            <origin xyz="0 0 0" rpy="0 0 0"/>
            <mass value="0.05"/>
            <inertia ixx="0.00001" ixy="0.0" ixz="0.0" 
                    iyy="0.00002" iyz="0.0" 
                    izz="0.00001"/>
        </inertial>
    </link>

    <link name="gripper_2">
        <visual>
            <origin rpy="0 0 0" xyz="0 0 0"/>
            <geometry>
                <mesh filename="package://arduinobot_description/meshes/gripper_2.dae" scale="5 5 5"/>
            </geometry>
            <material name="grey"/>
        </visual>
        <collision>
            <origin rpy="0 0 0" xyz="0 0 0"/>
            <geometry>
                <box size="0.02 0.04 0.02"/>
            </geometry>
        </collision>
        <inertial>
            <origin xyz="0 0 0" rpy="0 0 0"/>
            <mass value="0.05"/>
            <inertia ixx="0.00001" ixy="0.0" ixz="0.0" 
                    iyy="0.00002" iyz="0.0" 
                    izz="0.00001"/>
        </inertial>
    </link>

    <link name="gripper_3">
        <visual>
            <origin rpy="0 0 0" xyz="0 0 0"/>
            <geometry>
                <mesh filename="package://arduinobot_description/meshes/gripper_3.dae" scale="5 5 5"/>
            </geometry>
            <material name="grey"/>
        </visual>
        <collision>
            <origin rpy="0 0 0" xyz="0 0 0"/>
            <geometry>
                <box size="0.02 0.04 0.02"/>
            </geometry>
        </collision>
        <inertial>
            <origin xyz="0 0 0" rpy="0 0 0"/>
            <mass value="0.05"/>
            <inertia ixx="0.00001" ixy="0.0" ixz="0.0" 
                    iyy="0.00002" iyz="0.0" 
                    izz="0.00001"/>
        </inertial>
    </link>

    <!-- Gripper Joints -->
    <joint name="inner_circle_to_gripper_1" type="revolute">
        <parent link="inner_circle"/>
        <child link="gripper_1"/>
        <origin rpy="0 0 0" xyz="-0.08 -0.06 0.19"/>
        <axis xyz="1 0 0"/>
        <limit lower="-${PI/2}" upper="${PI/2}" effort="${effort}" velocity="${velocity}"/>
        <mimic joint="arm_2_to_inner_circle" multiplier="-1" offset="0"/>
        <dynamics damping="0.5" friction="0.1"/>
    </joint>

    <joint name="inner_circle_to_gripper_2" type="revolute">
        <parent link="inner_circle"/>
        <child link="gripper_2"/>
        <origin rpy="0 0 0" xyz="-0.17 0.09 0.17"/>
        <axis xyz="1 0 0"/>
        <limit lower="-${PI/2}" upper="${PI/2}" effort="${effort}" velocity="${velocity}"/>
        <mimic joint="arm_2_to_inner_circle" multiplier="-1" offset="0"/>
        <dynamics damping="0.5" friction="0.1"/>
    </joint>

    <joint name="inner_circle_to_gripper_3" type="revolute">
        <parent link="inner_circle"/>
        <child link="gripper_3"/>
        <origin rpy="0 0 ${4*PI/3}" xyz="-0.27 -0.04 0.16"/>
        <axis xyz="1 0 0"/>
        <limit lower="-${PI/2}" upper="${PI/2}" effort="${effort}" velocity="${velocity}"/>
        <mimic joint="arm_2_to_inner_circle" multiplier="-1" offset="0"/>
        <dynamics damping="0.5" friction="0.1"/>
    </joint>

</robot>