<?xml version="1.0"?>
<robot xmlns:xacro="http://www.ros.org/wiki/xacro">

    <!-- Include properties file -->
    <xacro:include filename="$(find arduinobot_description)/urdf/properties.xacro"/>

    <!-- Arm 1 -->
    <link name="arm_1">
        <visual>
            <origin rpy="0 0 0" xyz="0 0 0"/>
            <geometry>
                <mesh filename="package://arduinobot_description/meshes/arm_1.dae" scale="5 5 5"/>
            </geometry>
            <material name="grey">
                <color rgba="0.7 0.7 0.7 1.0"/>
            </material>
        </visual>
        <collision>
            <origin rpy="0 0 0" xyz="0 0 0"/>
            <geometry>
                <box size="0.03 0.03 0.15"/>
            </geometry>
        </collision>
        <inertial>
            <origin xyz="0 0 0" rpy="0 0 0"/>
            <mass value="0.25"/>
            <inertia ixx="0.0003" ixy="0.0" ixz="0.0" 
                    iyy="0.0003" iyz="0.0" 
                    izz="0.00001"/>
        </inertial>
    </link>

    <joint name="base_plate_to_arm_1" type="revolute">
        <parent link="base_plate"/>
        <child link="arm_1"/>
        <origin rpy="0 0 0" xyz="0 0 0.0012"/>
        <axis xyz="0 1 0"/>
        <limit lower="-${PI/3}" upper="${PI/3}" effort="${effort}" velocity="${velocity}"/>
        <dynamics damping="0.5" friction="0.1"/>
    </joint>

    <!-- Arm 2 -->
    <link name="arm_2">
        <visual>
            <origin rpy="0 0 0" xyz="0 0 0"/>
            <geometry>
                <mesh filename="package://arduinobot_description/meshes/arm_2.dae" scale="5 5 5"/>
            </geometry>
            <material name="grey">
                <color rgba="0.7 0.7 0.7 1.0"/>
            </material>
        </visual>
        <collision>
            <origin rpy="0 0 0" xyz="0 0 0"/>
            <geometry>
                <box size="0.03 0.03 0.15"/>
            </geometry>
        </collision>
        <inertial>
            <origin xyz="0 0 0" rpy="0 0 0"/>
            <mass value="0.2"/>
            <inertia ixx="0.0002" ixy="0.0" ixz="0.0" 
                    iyy="0.0002" iyz="0.0" 
                    izz="0.00001"/>
        </inertial>
    </link>

    <joint name="arm_1_to_arm_2" type="revolute">
        <parent link="arm_1"/>
        <child link="arm_2"/>
        <origin rpy="0 0 0" xyz="0 0 0.035"/>
        <axis xyz="0 1 0"/>
        <limit lower="-${PI/3}" upper="${PI/3}" effort="${effort}" velocity="${velocity}"/>
        <dynamics damping="0.5" friction="0.1"/>
    </joint>

    <!-- Arm 3 -->
    <link name="arm_3">
        <visual>
            <origin rpy="0 0 0" xyz="0 0 0"/>
            <geometry>
                <mesh filename="package://arduinobot_description/meshes/arm_3.dae" scale="5 5 5"/>
            </geometry>
            <material name="grey">
                <color rgba="0.7 0.7 0.7 1.0"/>
            </material>
        </visual>
        <collision>
            <origin rpy="0 0 0" xyz="0 0 0"/>
            <geometry>
                <box size="0.03 0.03 0.15"/>
            </geometry>
        </collision>
        <inertial>
            <origin xyz="0 0 0" rpy="0 0 0"/>
            <mass value="0.15"/>
            <inertia ixx="0.0002" ixy="0.0" ixz="0.0" 
                    iyy="0.0002" iyz="0.0" 
                    izz="0.00001"/>
        </inertial>
    </link>

    <joint name="arm_2_to_arm_3" type="revolute">
        <parent link="arm_2"/>
        <child link="arm_3"/>
        <origin rpy="0 0 0" xyz="0 0 0.035"/>
        <axis xyz="0 1 0"/>
        <limit lower="-${PI_2}" upper="${PI_2}" effort="${effort}" velocity="${velocity}"/>
        <dynamics damping="0.5" friction="0.1"/>
    </joint>

</robot>