<?xml version="1.0"?>
<robot xmlns:xacro="http://ros.org/wiki/xacro">
    <!-- inner_circle -->
    <link name="inner_circle">
        <visual>
            <origin rpy="0 0 0" xyz="0 0 0"/>
            <geometry>
                <mesh filename="package://arduinobot_description/meshes/inner_circle.dae" scale="5 5 5"/>
            </geometry>
            <material name="grey">
                <color rgba="0.7 0.7 0.7 1.0"/>
            </material>
        </visual>
        <collision>
            <origin rpy="0 0 0" xyz="0 0 0"/>
            <geometry>
                <cylinder radius="0.025" length="0.03"/>
            </geometry>
        </collision>
        <inertial>
            <origin xyz="0 0 0" rpy="0 0 0"/>
            <mass value="0.1"/>
            <inertia ixx="0.00001" ixy="0.0" ixz="0.0" 
                    iyy="0.00001" iyz="0.0" 
                    izz="0.00001"/>
        </inertial>
    </link>

    <joint name="arm_2_to_inner_circle" type="revolute">
        <parent link="arm_2"/>
        <child link="inner_circle"/>
        <origin rpy="0 0 0" xyz="-0.16 -0.01 0.21"/>
        <axis xyz="1 0 0"/>
        <limit lower="-${PI}" upper="0.0" effort="${effort}" velocity="${velocity}"/>
        <dynamics damping="0.5" friction="0.1"/>
    </joint> 

</robot>